outputs/states_FixedSpread_BuyPressure.csv
timestamp,strategy,regime,fair_price,best_bid,best_ask,recent_volatility,inventory,cash,pnl,bid_depth,ask_depth
1,FixedSpread,BuyPressure,99.996480,99.950000,100.050000,0.000211,0,0.000000,0.000000,1001,1000
2,FixedSpread,BuyPressure,99.993678,99.962344,100.050000,0.000367,0,0.000000,0.000000,1002,1000
3,FixedSpread,BuyPressure,100.003778,99.962344,100.050000,0.000951,0,0.000000,0.000000,1002,984
4,FixedSpread,BuyPressure,99.991943,99.950000,100.050000,0.001604,0,0.000000,0.000000,986,984
5,FixedSpread,BuyPressure,99.996284,99.950000,100.050000,0.001768,0,0.000000,0.000000,998,984
6,FixedSpread,BuyPressure,99.992282,99.950000,100.012758,0.001902,0,0.000000,0.000000,998,987
7,FixedSpread,BuyPressure,99.978695,99.950000,100.012758,0.002603,0,0.000000,0.000000,993,987
8,FixedSpread,BuyPressure,99.995176,99.950000,100.050000,0.003436,0,0.000000,0.000000,993,971
9,FixedSpread,BuyPressure,99.993906,99.953627,100.050000,0.003306,0,0.000000,0.000000,1002,971
10,FixedSpread,BuyPressure,100.002888,99.953627,100.050000,0.003646,0,0.000000,0.000000,1012,968
11,FixedSpread,BuyPressure,99.998238,99.953627,100.050000,0.003707,0,0.000000,0.000000,1029,968
12,FixedSpread,BuyPressure,99.984237,99.952888,100.050000,0.004324,4,-399.811552,0.125396,1016,968
13,FixedSpread,BuyPressure,99.991251,99.952888,100.052888,0.004486,2,-199.705776,0.276727,1016,958
14,FixedSpread,BuyPressure,99.991598,99.952888,100.052888,0.004237,2,-199.705776,0.277421,1016,965
15,FixedSpread,BuyPressure,99.995221,99.952888,100.052888,0.004200,2,-199.705776,0.284665,1024,965
16,FixedSpread,BuyPressure,100.011915,99.952888,100.052888,0.004950,-3,300.558664,0.522919,1024,960
17,FixedSpread,BuyPressure,100.027814,99.952888,100.052888,0.005607,-4,400.611552,0.500294,1024,959
18,FixedSpread,BuyPressure,100.031828,99.952888,100.052888,0.005511,-4,400.611552,0.484239,1024,962
19,FixedSpread,BuyPressure,100.041982,99.952888,100.100000,0.005790,-6,600.717328,0.465438,1024,954
20,FixedSpread,BuyPressure,100.049681,99.999681,100.099681,0.005905,-6,600.717328,0.419240,1034,944
21,FixedSpread,BuyPressure,100.047509,100.019836,100.099681,0.005681,-6,600.717328,0.432274,1044,944
22,FixedSpread,BuyPressure,100.059512,100.019836,100.099681,0.006060,-11,1101.215734,0.561099,1044,939
23,FixedSpread,BuyPressure,100.073183,100.019836,100.100000,0.006517,-16,1601.714140,0.543220,1044,929
24,FixedSpread,BuyPressure,100.076951,100.022246,100.100000,0.006352,-16,1601.714140,0.482932,1060,929
25,FixedSpread,BuyPressure,100.080763,100.022246,100.100000,0.006199,-16,1601.714140,0.421933,1077,929
26,FixedSpread,BuyPressure,100.091283,100.022246,100.100000,0.006459,-16,1601.714140,0.253611,1077,911
27,FixedSpread,BuyPressure,100.088151,100.022246,100.100000,0.006259,-16,1601.714140,0.303724,1088,911
28,FixedSpread,BuyPressure,100.088971,100.022246,100.100000,0.005933,-16,1601.714140,0.290608,1105,911
29,FixedSpread,BuyPressure,100.081269,100.019836,100.100000,0.006039,-16,1601.714140,0.413837,1085,911
30,FixedSpread,BuyPressure,100.089300,100.039300,100.139300,0.006158,-16,1601.714140,0.285333,1095,905
31,FixedSpread,BuyPressure,100.091191,100.039300,100.139300,0.005902,-16,1601.714140,0.255079,1098,905
32,FixedSpread,BuyPressure,100.107751,100.039300,100.150000,0.006542,-26,2603.107145,0.305620,1098,889
33,FixedSpread,BuyPressure,100.112523,100.039300,100.150000,0.006436,-26,2603.107145,0.181556,1102,889
34,FixedSpread,BuyPressure,100.128874,100.039300,100.150000,0.007030,-26,2603.107145,-0.243567,1102,869
35,FixedSpread,BuyPressure,100.137445,100.039300,100.181130,0.007123,-26,2603.107145,-0.466414,1102,855
36,FixedSpread,BuyPressure,100.147371,100.039300,100.200000,0.007291,-26,2603.107145,-0.724506,1102,835
37,FixedSpread,BuyPressure,100.147459,100.039300,100.200000,0.006859,-26,2603.107145,-0.726787,1120,835
38,FixedSpread,BuyPressure,100.148519,100.055935,100.200000,0.006511,-26,2603.107145,-0.754353,1132,835
39,FixedSpread,BuyPressure,100.134516,100.055935,100.200000,0.006961,-26,2603.107145,-0.390263,1129,835
40,FixedSpread,BuyPressure,100.148024,100.098024,100.198024,0.007353,-26,2603.107145,-0.741489,1139,830
41,FixedSpread,BuyPressure,100.164053,100.098024,100.200000,0.007874,-36,3605.087389,-0.818523,1139,812
42,FixedSpread,BuyPressure,100.160566,100.098024,100.200000,0.007611,-36,3605.087389,-0.692981,1153,812
43,FixedSpread,BuyPressure,100.163549,100.098024,100.200000,0.007333,-36,3605.087389,-0.800379,1153,819
44,FixedSpread,BuyPressure,100.173002,100.098024,100.250000,0.007460,-36,3605.087389,-1.140696,1153,800
45,FixedSpread,BuyPressure,100.172670,100.098024,100.194270,0.007033,-36,3605.087389,-1.128732,1153,802
46,FixedSpread,BuyPressure,100.170317,100.111474,100.194270,0.006752,-36,3605.087389,-1.044005,1157,802
47,FixedSpread,BuyPressure,100.167427,100.131370,100.194270,0.006520,-36,3605.087389,-0.939988,1166,802
48,FixedSpread,BuyPressure,100.179827,100.131370,100.250000,0.006873,-36,3605.087389,-1.386382,1166,793
49,FixedSpread,BuyPressure,100.177989,100.131370,100.250000,0.006571,-36,3605.087389,-1.320218,1166,810
50,FixedSpread,BuyPressure,100.192277,100.142277,100.242277,0.007034,-36,3605.087389,-1.834574,1176,819
51,FixedSpread,BuyPressure,100.206899,100.142277,100.242277,0.007489,-42,4206.541050,-2.148713,1176,813
52,FixedSpread,BuyPressure,100.217635,100.142277,100.250000,0.007684,-46,4607.510157,-2.501047,1176,797
53,FixedSpread,BuyPressure,100.219124,100.145737,100.250000,0.007312,-46,4607.510157,-2.569540,1191,797
54,FixedSpread,BuyPressure,100.214722,100.145737,100.250000,0.007138,-46,4607.510157,-2.367043,1191,808
55,FixedSpread,BuyPressure,100.225008,100.145737,100.250000,0.007327,-46,4607.510157,-2.840225,1191,801
56,FixedSpread,BuyPressure,100.233172,100.145737,100.276026,0.007377,-46,4607.510157,-3.215759,1191,784
57,FixedSpread,BuyPressure,100.245447,100.145737,100.276026,0.007671,-46,4607.510157,-3.780389,1191,783
58,FixedSpread,BuyPressure,100.235935,100.145737,100.276026,0.007781,-46,4607.510157,-3.342834,1180,783
59,FixedSpread,BuyPressure,100.247644,100.145737,100.300000,0.008017,-46,4607.510157,-3.881452,1180,764
60,FixedSpread,BuyPressure,100.250491,100.200491,100.300000,0.007707,-46,4607.510157,-4.012441,1207,774
61,FixedSpread,BuyPressure,100.258287,100.200491,100.300000,0.007712,-46,4607.510157,-4.371037,1207,765
62,FixedSpread,BuyPressure,100.269085,100.200491,100.300000,0.007897,-46,4607.510157,-4.867753,1207,753
63,FixedSpread,BuyPressure,100.280273,100.200491,100.300000,0.008095,-46,4607.510157,-5.382400,1207,746
64,FixedSpread,BuyPressure,100.281330,100.200491,100.300000,0.007672,-46,4607.510157,-5.431013,1216,746
65,FixedSpread,BuyPressure,100.268963,100.145737,100.300000,0.007954,-36,3605.505245,-4.177423,1205,746
66,FixedSpread,BuyPressure,100.267612,100.145737,100.300000,0.007558,-36,3605.505245,-4.128772,1205,761
67,FixedSpread,BuyPressure,100.275592,100.145737,100.300000,0.007583,-36,3605.505245,-4.416067,1205,755
68,FixedSpread,BuyPressure,100.283583,100.145737,100.349740,0.007608,-46,4608.510157,-4.534661,1205,735
69,FixedSpread,BuyPressure,100.298248,100.145737,100.349740,0.008031,-46,4608.510157,-5.209242,1205,734
70,FixedSpread,BuyPressure,100.281922,100.231922,100.331922,0.008529,-39,3907.514220,-3.480731,1205,744
71,FixedSpread,BuyPressure,100.292331,100.231922,100.331922,0.008642,-43,4308.841907,-3.728346,1205,740
72,FixedSpread,BuyPressure,100.302584,100.231922,100.350000,0.008738,-49,4910.833438,-3.993188,1205,730
73,FixedSpread,BuyPressure,100.301473,100.231922,100.350000,0.008281,-49,4910.833438,-3.938717,1217,730
74,FixedSpread,BuyPressure,100.303065,100.231922,100.350000,0.007879,-49,4910.833438,-4.016751,1217,739
75,FixedSpread,BuyPressure,100.295052,100.231922,100.350000,0.007887,-45,4509.905751,-3.371596,1213,739
76,FixedSpread,BuyPressure,100.302849,100.231922,100.350000,0.007882,-45,4509.905751,-3.722462,1213,732
77,FixedSpread,BuyPressure,100.287183,100.131370,100.350000,0.008349,-36,3608.087389,-2.251188,1198,732
78,FixedSpread,BuyPressure,100.289534,100.131370,100.329191,0.007989,-36,3608.087389,-2.335850,1198,750
