outputs/states_FixedSpread_SellPressure.csv
timestamp,strategy,regime,fair_price,best_bid,best_ask,recent_volatility,inventory,cash,pnl,bid_depth,ask_depth
1,FixedSpread,SellPressure,100.011979,99.950000,100.050000,0.000719,0,0.000000,0.000000,1000,998
2,FixedSpread,SellPressure,100.002156,99.950000,100.050000,0.001265,0,0.000000,0.000000,997,998
3,FixedSpread,SellPressure,99.989245,99.950000,100.050000,0.001964,0,0.000000,0.000000,993,998
4,FixedSpread,SellPressure,99.991330,99.950000,100.050000,0.001971,0,0.000000,0.000000,1003,998
5,FixedSpread,SellPressure,99.993195,99.950000,100.050000,0.001965,0,0.000000,0.000000,1003,1007
6,FixedSpread,SellPressure,99.977505,99.950000,100.050000,0.002788,0,0.000000,0.000000,983,1007
7,FixedSpread,SellPressure,99.967849,99.950000,100.050000,0.003200,0,0.000000,0.000000,972,1007
8,FixedSpread,SellPressure,99.956059,99.950000,100.050000,0.003716,0,0.000000,0.000000,964,1007
9,FixedSpread,SellPressure,99.960139,99.950000,100.050000,0.003737,0,0.000000,0.000000,982,1007
10,FixedSpread,SellPressure,99.952986,99.902986,100.002986,0.003942,0,0.000000,0.000000,976,1017
11,FixedSpread,SellPressure,99.951878,99.902986,100.002986,0.003772,0,0.000000,0.000000,976,1020
12,FixedSpread,SellPressure,99.936908,99.902986,100.002986,0.004444,2,-199.805972,0.067845,974,1020
13,FixedSpread,SellPressure,99.929478,99.900000,100.002986,0.004623,10,-999.029861,0.264918,963,1020
14,FixedSpread,SellPressure,99.926387,99.900000,99.992527,0.004531,10,-999.029861,0.234006,963,1029
15,FixedSpread,SellPressure,99.912185,99.900000,99.992527,0.005112,10,-999.029861,0.091988,958,1029
16,FixedSpread,SellPressure,99.910898,99.900000,99.992527,0.004882,10,-999.029861,0.079120,975,1029
17,FixedSpread,SellPressure,99.909177,99.900000,99.977444,0.004692,10,-999.029861,0.061911,975,1033
18,FixedSpread,SellPressure,99.899678,99.900000,99.977444,0.004981,10,-999.029861,-0.033081,962,1033
19,FixedSpread,SellPressure,99.889572,99.900000,99.977444,0.005288,10,-999.029861,-0.134143,958,1033
20,FixedSpread,SellPressure,99.888335,99.900000,99.938335,0.005045,10,-999.029861,-0.146511,984,1043
21,FixedSpread,SellPressure,99.888670,99.900000,99.938335,0.004763,10,-999.029861,-0.143162,994,1043
22,FixedSpread,SellPressure,99.898384,99.900000,99.938335,0.005060,2,-199.523181,0.273588,994,1035
23,FixedSpread,SellPressure,99.902563,99.900000,99.938335,0.005007,2,-199.523181,0.281946,994,1054
24,FixedSpread,SellPressure,99.911079,99.900000,99.992527,0.005217,0,0.353489,0.353489,994,1048
25,FixedSpread,SellPressure,99.903967,99.900000,99.992527,0.005331,0,0.353489,0.353489,988,1048
26,FixedSpread,SellPressure,99.920637,99.900000,100.002986,0.006011,-2,200.359461,0.518188,988,1037
27,FixedSpread,SellPressure,99.912968,99.900000,100.002986,0.006111,-2,200.359461,0.533526,977,1037
28,FixedSpread,SellPressure,99.905522,99.852325,100.002986,0.006191,-2,200.359461,0.548417,969,1037
29,FixedSpread,SellPressure,99.913502,99.852325,100.002986,0.006298,-5,500.368419,0.800907,969,1034
30,FixedSpread,SellPressure,99.902340,99.852340,99.952340,0.006590,-5,500.368419,0.856721,970,1044
31,FixedSpread,SellPressure,99.889002,99.850000,99.952340,0.006995,5,-498.154977,1.290035,957,1044
32,FixedSpread,SellPressure,99.893908,99.850000,99.952340,0.006870,5,-498.154977,1.314564,957,1062
33,FixedSpread,SellPressure,99.890194,99.850000,99.947536,0.006680,5,-498.154977,1.295996,957,1081
34,FixedSpread,SellPressure,99.904592,99.850000,99.947536,0.007143,5,-498.154977,1.367983,957,1080
35,FixedSpread,SellPressure,99.906284,99.850000,99.947536,0.006816,5,-498.154977,1.376445,957,1095
36,FixedSpread,SellPressure,99.892625,99.850000,99.947536,0.007227,5,-498.154977,1.308151,939,1095
37,FixedSpread,SellPressure,99.878861,99.850000,99.947536,0.007619,5,-498.154977,1.239329,919,1095
38,FixedSpread,SellPressure,99.866345,99.838335,99.947536,0.007913,11,-1097.184986,1.344805,905,1095
39,FixedSpread,SellPressure,99.852490,99.809314,99.947536,0.008269,15,-1496.538326,1.249030,889,1095
40,FixedSpread,SellPressure,99.845288,99.800000,99.895288,0.008205,15,-1496.538326,1.140987,889,1105
41,FixedSpread,SellPressure,99.830495,99.800000,99.895288,0.008601,15,-1496.538326,0.919097,886,1105
42,FixedSpread,SellPressure,99.834716,99.800000,99.895288,0.008338,15,-1496.538326,0.982417,887,1105
43,FixedSpread,SellPressure,99.839512,99.800000,99.895288,0.008125,15,-1496.538326,1.054352,903,1105
44,FixedSpread,SellPressure,99.835380,99.800000,99.895288,0.007886,15,-1496.538326,0.992373,903,1119
45,FixedSpread,SellPressure,99.823188,99.800000,99.895288,0.008144,15,-1496.538326,0.809494,896,1119
46,FixedSpread,SellPressure,99.831191,99.800000,99.915796,0.008136,5,-497.585451,1.570503,896,1106
47,FixedSpread,SellPressure,99.839929,99.800000,99.947536,0.008172,5,-497.585451,1.614192,896,1092
48,FixedSpread,SellPressure,99.829750,99.800000,99.947536,0.008292,5,-497.585451,1.563301,895,1092
49,FixedSpread,SellPressure,99.816858,99.800000,99.947536,0.008568,5,-497.585451,1.498841,884,1092
50,FixedSpread,SellPressure,99.817683,99.800000,99.854285,0.008103,5,-497.585451,1.502962,894,1111
51,FixedSpread,SellPressure,99.829157,99.800000,99.867683,0.008306,2,-197.982403,1.675910,894,1099
52,FixedSpread,SellPressure,99.817692,99.800000,99.867683,0.008495,2,-197.982403,1.652980,878,1099
53,FixedSpread,SellPressure,99.814373,99.800000,99.867683,0.008185,2,-197.982403,1.646342,878,1106
54,FixedSpread,SellPressure,99.803583,99.767683,99.867683,0.008341,14,-1395.470644,1.779513,859,1106
55,FixedSpread,SellPressure,99.791791,99.760199,99.867683,0.008548,22,-2193.612104,1.807298,846,1106
56,FixedSpread,SellPressure,99.792512,99.760199,99.866460,0.008078,22,-2193.612104,1.823157,846,1110
57,FixedSpread,SellPressure,99.776778,99.760199,99.866460,0.008538,22,-2193.612104,1.477012,841,1110
58,FixedSpread,SellPressure,99.772399,99.760199,99.850441,0.008288,22,-2193.612104,1.380679,841,1112
59,FixedSpread,SellPressure,99.755610,99.751573,99.850441,0.008798,22,-2193.612104,1.011305,825,1112
60,FixedSpread,SellPressure,99.739572,99.751573,99.789572,0.009233,22,-2193.612104,0.658481,829,1122
61,FixedSpread,SellPressure,99.730363,99.750000,99.789572,0.009231,22,-2193.612104,0.455889,809,1122
62,FixedSpread,SellPressure,99.725508,99.750000,99.789572,0.008969,22,-2193.612104,0.349075,823,1122
63,FixedSpread,SellPressure,99.718389,99.750000,99.789572,0.008858,22,-2193.612104,0.192445,819,1122
64,FixedSpread,SellPressure,99.703751,99.750000,99.789572,0.009204,22,-2193.612104,-0.129572,814,1122
65,FixedSpread,SellPressure,99.715825,99.750000,99.867683,0.009377,10,-995.981018,1.177227,814,1104
66,FixedSpread,SellPressure,99.712229,99.750000,99.797634,0.009030,10,-995.981018,1.141275,814,1121
67,FixedSpread,SellPressure,99.699161,99.750000,99.797634,0.009272,10,-995.981018,1.010595,805,1121
68,FixedSpread,SellPressure,99.699534,99.750000,99.797634,0.008738,10,-995.981018,1.014320,822,1121
69,FixedSpread,SellPressure,99.712505,99.750000,99.867683,0.008992,10,-995.981018,1.144036,822,1104
70,FixedSpread,SellPressure,99.699798,99.718226,99.749798,0.009215,3,-297.731018,1.368376,818,1107
71,FixedSpread,SellPressure,99.692340,99.718226,99.749798,0.009110,3,-297.731018,1.346002,808,1107
72,FixedSpread,SellPressure,99.683398,99.700412,99.749798,0.009099,3,-297.731018,1.319177,790,1107
73,FixedSpread,SellPressure,99.668837,99.700000,99.749798,0.009427,3,-297.731018,1.275494,771,1107
74,FixedSpread,SellPressure,99.664657,99.700000,99.749798,0.009112,3,-297.731018,1.262954,772,1107
75,FixedSpread,SellPressure,99.662536,99.700000,99.749798,0.008693,3,-297.731018,1.256588,771,1107
76,FixedSpread,SellPressure,99.663916,99.700000,99.749798,0.008254,3,-297.731018,1.260730,771,1118
77,FixedSpread,SellPressure,99.648312,99.700000,99.749798,0.008695,3,-297.731018,1.213918,764,1118
78,FixedSpread,SellPressure,99.643642,99.700000,99.749798,0.008454,3,-297.731018,1.199908,764,1134
79,FixedSpread,SellPressure,99.654260,99.700000,99.828890,0.008584,0,1.518376,1.518376,764,1127
80,FixedSpread,SellPressure,99.645025,99.700000,99.828890,0.008623,-10,998.518376,2.068122,758,1127
